/var/spool/slurm/d/job03090/slurm_script: line 15: {workdir}/3090.stdout: No such file or directory
/var/spool/slurm/d/job03090/slurm_script: line 16: {workdir}/3090.stdout: No such file or directory
/var/spool/slurm/d/job03090/slurm_script: line 17: {workdir}/3090.stdout: No such file or directory
/var/spool/slurm/d/job03090/slurm_script: line 18: {workdir}/3090.stdout: No such file or directory
/var/spool/slurm/d/job03090/slurm_script: line 19: {workdir}/3090.stdout: No such file or directory
/var/spool/slurm/d/job03090/slurm_script: line 20: {workdir}/3090.stdout: No such file or directory
0: FAISS library was not found.
0: FAISS not available. Switching to standard nearest neighbors search implementation.
0: FAISS library was not found.
0: FAISS not available. Switching to standard nearest neighbors search implementation.
2: FAISS library was not found.
2: FAISS not available. Switching to standard nearest neighbors search implementation.
1: FAISS library was not found.
1: FAISS not available. Switching to standard nearest neighbors search implementation.
3: FAISS library was not found.
3: FAISS not available. Switching to standard nearest neighbors search implementation.
1: FAISS library was not found.
1: FAISS not available. Switching to standard nearest neighbors search implementation.
2: FAISS library was not found.
2: FAISS not available. Switching to standard nearest neighbors search implementation.
3: FAISS library was not found.
3: FAISS not available. Switching to standard nearest neighbors search implementation.
0: Traceback (most recent call last):
0:   File "train.py", line 344, in <module>
0:     check_data_params(params)
0:   File "/home/menekse/xlm/Animal/XLM-master/src/data/loader.py", line 315, in check_data_params
0:     assert os.path.isdir(params.data_path), params.data_path
0: AssertionError: /data/shared/ConceptualCaptions/XLM_data/49k
0: Traceback (most recent call last):
0:   File "train.py", line 344, in <module>
0:     check_data_params(params)
0:   File "/home/menekse/xlm/Animal/XLM-master/src/data/loader.py", line 315, in check_data_params
0:     assert os.path.isdir(params.data_path), params.data_path
0: AssertionError: /data/shared/ConceptualCaptions/XLM_data/49k
2: Traceback (most recent call last):
2:   File "train.py", line 344, in <module>
2:     check_data_params(params)
2:   File "/home/menekse/xlm/Animal/XLM-master/src/data/loader.py", line 315, in check_data_params
2:     assert os.path.isdir(params.data_path), params.data_path
2: AssertionError: /data/shared/ConceptualCaptions/XLM_data/49k
3: Traceback (most recent call last):
3:   File "train.py", line 344, in <module>
2: Traceback (most recent call last):
2:   File "train.py", line 344, in <module>
3:     check_data_params(params)
3:   File "/home/menekse/xlm/Animal/XLM-master/src/data/loader.py", line 315, in check_data_params
2:     check_data_params(params)
2:   File "/home/menekse/xlm/Animal/XLM-master/src/data/loader.py", line 315, in check_data_params
3:     assert os.path.isdir(params.data_path), params.data_path
3: AssertionError: /data/shared/ConceptualCaptions/XLM_data/49k
2:     assert os.path.isdir(params.data_path), params.data_path
2: AssertionError: /data/shared/ConceptualCaptions/XLM_data/49k
1: Traceback (most recent call last):
1:   File "train.py", line 344, in <module>
1:     check_data_params(params)
1:   File "/home/menekse/xlm/Animal/XLM-master/src/data/loader.py", line 315, in check_data_params
1:     assert os.path.isdir(params.data_path), params.data_path
1: AssertionError: /data/shared/ConceptualCaptions/XLM_data/49k
3: Traceback (most recent call last):
3:   File "train.py", line 344, in <module>
3:     check_data_params(params)
3:   File "/home/menekse/xlm/Animal/XLM-master/src/data/loader.py", line 315, in check_data_params
3:     assert os.path.isdir(params.data_path), params.data_path
3: AssertionError: /data/shared/ConceptualCaptions/XLM_data/49k
1: Traceback (most recent call last):
1:   File "train.py", line 344, in <module>
1:     check_data_params(params)
1:   File "/home/menekse/xlm/Animal/XLM-master/src/data/loader.py", line 315, in check_data_params
1:     assert os.path.isdir(params.data_path), params.data_path
1: AssertionError: /data/shared/ConceptualCaptions/XLM_data/49k
0: Traceback (most recent call last):
0:   File "/usr/lib64/python3.6/runpy.py", line 193, in _run_module_as_main
0:     "__main__", mod_spec)
0:   File "/usr/lib64/python3.6/runpy.py", line 85, in _run_code
0:     exec(code, run_globals)
0:   File "/home/menekse/virtualenvs/torch_env/lib/python3.6/site-packages/torch/distributed/launch.py", line 263, in <module>
0:     main()
0:   File "/home/menekse/virtualenvs/torch_env/lib/python3.6/site-packages/torch/distributed/launch.py", line 259, in main
0:     cmd=cmd)
0: subprocess.CalledProcessError: Command '['/home/menekse/virtualenvs/torch_env/bin/python', '-u', 'train.py', '--local_rank=1', '--exp_name', 'xlm_en_de_tlm', '--dump_path', '/data/menekse/dumped', '--data_path', '/data/shared/ConceptualCaptions/XLM_data/49k', '--lgs', 'en-de', '--clm_steps', '', '--mlm_steps', 'en-de', '--emb_dim', '512', '--n_layers', '6', '--n_heads', '8', '--dropout', '0.1', '--attention_dropout', '0.1', '--gelu_activation', 'true', '--batch_size', '32', '--bptt', '256', '--optimizer', 'adam,lr=0.0001', '--epoch_size', '300000', '--max_epoch', '100000', '--validation_metrics', 'valid_en_de_mlm_ppl', '--stopping_criterion', '_valid_mlm_ppl,25', '--fp16', 'false', '--image_names', '/data/shared/ConceptualCaptions/XLM_data/50k']' returned non-zero exit status 1.
srun: error: hanabi: task 0: Exited with exit code 1
3: Traceback (most recent call last):
3:   File "/usr/lib64/python3.6/runpy.py", line 193, in _run_module_as_main
3:     "__main__", mod_spec)
3:   File "/usr/lib64/python3.6/runpy.py", line 85, in _run_code
3:     exec(code, run_globals)
3:   File "/home/menekse/virtualenvs/torch_env/lib/python3.6/site-packages/torch/distributed/launch.py", line 263, in <module>
3:     main()
3:   File "/home/menekse/virtualenvs/torch_env/lib/python3.6/site-packages/torch/distributed/launch.py", line 259, in main
3:     cmd=cmd)
3: subprocess.CalledProcessError: Command '['/home/menekse/virtualenvs/torch_env/bin/python', '-u', 'train.py', '--local_rank=1', '--exp_name', 'xlm_en_de_tlm', '--dump_path', '/data/menekse/dumped', '--data_path', '/data/shared/ConceptualCaptions/XLM_data/49k', '--lgs', 'en-de', '--clm_steps', '', '--mlm_steps', 'en-de', '--emb_dim', '512', '--n_layers', '6', '--n_heads', '8', '--dropout', '0.1', '--attention_dropout', '0.1', '--gelu_activation', 'true', '--batch_size', '32', '--bptt', '256', '--optimizer', 'adam,lr=0.0001', '--epoch_size', '300000', '--max_epoch', '100000', '--validation_metrics', 'valid_en_de_mlm_ppl', '--stopping_criterion', '_valid_mlm_ppl,25', '--fp16', 'false', '--image_names', '/data/shared/ConceptualCaptions/XLM_data/50k']' returned non-zero exit status 1.
1: Traceback (most recent call last):
1:   File "/usr/lib64/python3.6/runpy.py", line 193, in _run_module_as_main
1:     "__main__", mod_spec)
1:   File "/usr/lib64/python3.6/runpy.py", line 85, in _run_code
1:     exec(code, run_globals)
1:   File "/home/menekse/virtualenvs/torch_env/lib/python3.6/site-packages/torch/distributed/launch.py", line 263, in <module>
1:     main()
1:   File "/home/menekse/virtualenvs/torch_env/lib/python3.6/site-packages/torch/distributed/launch.py", line 259, in main
1:     cmd=cmd)
1: subprocess.CalledProcessError: Command '['/home/menekse/virtualenvs/torch_env/bin/python', '-u', 'train.py', '--local_rank=1', '--exp_name', 'xlm_en_de_tlm', '--dump_path', '/data/menekse/dumped', '--data_path', '/data/shared/ConceptualCaptions/XLM_data/49k', '--lgs', 'en-de', '--clm_steps', '', '--mlm_steps', 'en-de', '--emb_dim', '512', '--n_layers', '6', '--n_heads', '8', '--dropout', '0.1', '--attention_dropout', '0.1', '--gelu_activation', 'true', '--batch_size', '32', '--bptt', '256', '--optimizer', 'adam,lr=0.0001', '--epoch_size', '300000', '--max_epoch', '100000', '--validation_metrics', 'valid_en_de_mlm_ppl', '--stopping_criterion', '_valid_mlm_ppl,25', '--fp16', 'false', '--image_names', '/data/shared/ConceptualCaptions/XLM_data/50k']' returned non-zero exit status 1.
2: Traceback (most recent call last):
2:   File "/usr/lib64/python3.6/runpy.py", line 193, in _run_module_as_main
2:     "__main__", mod_spec)
2:   File "/usr/lib64/python3.6/runpy.py", line 85, in _run_code
2:     exec(code, run_globals)
2:   File "/home/menekse/virtualenvs/torch_env/lib/python3.6/site-packages/torch/distributed/launch.py", line 263, in <module>
2:     main()
2:   File "/home/menekse/virtualenvs/torch_env/lib/python3.6/site-packages/torch/distributed/launch.py", line 259, in main
2:     cmd=cmd)
2: subprocess.CalledProcessError: Command '['/home/menekse/virtualenvs/torch_env/bin/python', '-u', 'train.py', '--local_rank=1', '--exp_name', 'xlm_en_de_tlm', '--dump_path', '/data/menekse/dumped', '--data_path', '/data/shared/ConceptualCaptions/XLM_data/49k', '--lgs', 'en-de', '--clm_steps', '', '--mlm_steps', 'en-de', '--emb_dim', '512', '--n_layers', '6', '--n_heads', '8', '--dropout', '0.1', '--attention_dropout', '0.1', '--gelu_activation', 'true', '--batch_size', '32', '--bptt', '256', '--optimizer', 'adam,lr=0.0001', '--epoch_size', '300000', '--max_epoch', '100000', '--validation_metrics', 'valid_en_de_mlm_ppl', '--stopping_criterion', '_valid_mlm_ppl,25', '--fp16', 'false', '--image_names', '/data/shared/ConceptualCaptions/XLM_data/50k']' returned non-zero exit status 1.
srun: error: hanabi: task 3: Exited with exit code 1
srun: error: hanabi: task 1: Exited with exit code 1
srun: error: hanabi: task 2: Exited with exit code 1
